2025-08-11 15:59:49,614 INFO    MainThread:1341571 [wandb_setup.py:_flush():79] Current SDK version is 0.18.7
2025-08-11 15:59:49,614 INFO    MainThread:1341571 [wandb_setup.py:_flush():79] Configure stats pid to 1341571
2025-08-11 15:59:49,614 INFO    MainThread:1341571 [wandb_setup.py:_flush():79] Loading settings from /root/.config/wandb/settings
2025-08-11 15:59:49,614 INFO    MainThread:1341571 [wandb_setup.py:_flush():79] Loading settings from /pfs/yangyuanming/code2/download/wandb/settings
2025-08-11 15:59:49,614 INFO    MainThread:1341571 [wandb_setup.py:_flush():79] Loading settings from environment variables: {}
2025-08-11 15:59:49,614 INFO    MainThread:1341571 [wandb_setup.py:_flush():79] Applying setup settings: {'mode': None, '_disable_service': None}
2025-08-11 15:59:49,614 INFO    MainThread:1341571 [wandb_setup.py:_flush():79] Inferring run settings from compute environment: {'program': '<python with no main file>'}
2025-08-11 15:59:49,614 INFO    MainThread:1341571 [wandb_setup.py:_flush():79] Applying login settings: {}
2025-08-11 15:59:49,614 INFO    MainThread:1341571 [wandb_setup.py:_flush():79] Applying login settings: {'api_key': '***REDACTED***'}
2025-08-11 15:59:49,614 INFO    MainThread:1341571 [wandb_init.py:_log_setup():533] Logging user logs to /pfs/yangyuanming/code2/download/wandb/run-20250811_155949-qy5o0skg/logs/debug.log
2025-08-11 15:59:49,614 INFO    MainThread:1341571 [wandb_init.py:_log_setup():534] Logging internal logs to /pfs/yangyuanming/code2/download/wandb/run-20250811_155949-qy5o0skg/logs/debug-internal.log
2025-08-11 15:59:49,614 INFO    MainThread:1341571 [wandb_init.py:init():619] calling init triggers
2025-08-11 15:59:49,614 INFO    MainThread:1341571 [wandb_init.py:init():626] wandb.init called with sweep_config: {}
config: {}
2025-08-11 15:59:49,614 INFO    MainThread:1341571 [wandb_init.py:init():669] starting backend
2025-08-11 15:59:49,614 INFO    MainThread:1341571 [wandb_init.py:init():673] sending inform_init request
2025-08-11 15:59:49,615 INFO    MainThread:1341571 [backend.py:_multiprocessing_setup():104] multiprocessing start_methods=fork,spawn,forkserver, using: spawn
2025-08-11 15:59:49,615 INFO    MainThread:1341571 [wandb_init.py:init():686] backend started and connected
2025-08-11 15:59:49,616 INFO    MainThread:1341571 [wandb_init.py:init():781] updated telemetry
2025-08-11 15:59:49,620 INFO    MainThread:1341571 [wandb_init.py:init():814] communicating run to backend with 90.0 second timeout
2025-08-11 16:00:48,252 INFO    Thread-1 (wrapped_target):1341571 [retry.py:__call__():172] Retry attempt failed:
Traceback (most recent call last):
  File "/opt/conda/envs/flow_grpo/lib/python3.10/site-packages/urllib3/connection.py", line 198, in _new_conn
    sock = connection.create_connection(
  File "/opt/conda/envs/flow_grpo/lib/python3.10/site-packages/urllib3/util/connection.py", line 85, in create_connection
    raise err
  File "/opt/conda/envs/flow_grpo/lib/python3.10/site-packages/urllib3/util/connection.py", line 73, in create_connection
    sock.connect(sa)
TimeoutError: timed out

The above exception was the direct cause of the following exception:

Traceback (most recent call last):
  File "/opt/conda/envs/flow_grpo/lib/python3.10/site-packages/urllib3/connectionpool.py", line 787, in urlopen
    response = self._make_request(
  File "/opt/conda/envs/flow_grpo/lib/python3.10/site-packages/urllib3/connectionpool.py", line 488, in _make_request
    raise new_e
  File "/opt/conda/envs/flow_grpo/lib/python3.10/site-packages/urllib3/connectionpool.py", line 464, in _make_request
    self._validate_conn(conn)
  File "/opt/conda/envs/flow_grpo/lib/python3.10/site-packages/urllib3/connectionpool.py", line 1093, in _validate_conn
    conn.connect()
  File "/opt/conda/envs/flow_grpo/lib/python3.10/site-packages/urllib3/connection.py", line 753, in connect
    self.sock = sock = self._new_conn()
  File "/opt/conda/envs/flow_grpo/lib/python3.10/site-packages/urllib3/connection.py", line 207, in _new_conn
    raise ConnectTimeoutError(
urllib3.exceptions.ConnectTimeoutError: (<urllib3.connection.HTTPSConnection object at 0x7fb5c83d6260>, 'Connection to api.wandb.ai timed out. (connect timeout=20)')

The above exception was the direct cause of the following exception:

Traceback (most recent call last):
  File "/opt/conda/envs/flow_grpo/lib/python3.10/site-packages/requests/adapters.py", line 667, in send
    resp = conn.urlopen(
  File "/opt/conda/envs/flow_grpo/lib/python3.10/site-packages/urllib3/connectionpool.py", line 841, in urlopen
    retries = retries.increment(
  File "/opt/conda/envs/flow_grpo/lib/python3.10/site-packages/urllib3/util/retry.py", line 519, in increment
    raise MaxRetryError(_pool, url, reason) from reason  # type: ignore[arg-type]
urllib3.exceptions.MaxRetryError: HTTPSConnectionPool(host='api.wandb.ai', port=443): Max retries exceeded with url: /graphql (Caused by ConnectTimeoutError(<urllib3.connection.HTTPSConnection object at 0x7fb5c83d6260>, 'Connection to api.wandb.ai timed out. (connect timeout=20)'))

During handling of the above exception, another exception occurred:

Traceback (most recent call last):
  File "/opt/conda/envs/flow_grpo/lib/python3.10/site-packages/wandb/sdk/lib/retry.py", line 131, in __call__
    result = self._call_fn(*args, **kwargs)
  File "/opt/conda/envs/flow_grpo/lib/python3.10/site-packages/wandb/sdk/internal/internal_api.py", line 400, in execute
    return self.client.execute(*args, **kwargs)  # type: ignore
  File "/opt/conda/envs/flow_grpo/lib/python3.10/site-packages/wandb/vendor/gql-0.2.0/wandb_gql/client.py", line 52, in execute
    result = self._get_result(document, *args, **kwargs)
  File "/opt/conda/envs/flow_grpo/lib/python3.10/site-packages/wandb/vendor/gql-0.2.0/wandb_gql/client.py", line 60, in _get_result
    return self.transport.execute(document, *args, **kwargs)
  File "/opt/conda/envs/flow_grpo/lib/python3.10/site-packages/wandb/sdk/lib/gql_request.py", line 58, in execute
    request = self.session.post(self.url, **post_args)
  File "/opt/conda/envs/flow_grpo/lib/python3.10/site-packages/requests/sessions.py", line 637, in post
    return self.request("POST", url, data=data, json=json, **kwargs)
  File "/opt/conda/envs/flow_grpo/lib/python3.10/site-packages/requests/sessions.py", line 589, in request
    resp = self.send(prep, **send_kwargs)
  File "/opt/conda/envs/flow_grpo/lib/python3.10/site-packages/requests/sessions.py", line 703, in send
    r = adapter.send(request, **kwargs)
  File "/opt/conda/envs/flow_grpo/lib/python3.10/site-packages/requests/adapters.py", line 688, in send
    raise ConnectTimeout(e, request=request)
requests.exceptions.ConnectTimeout: HTTPSConnectionPool(host='api.wandb.ai', port=443): Max retries exceeded with url: /graphql (Caused by ConnectTimeoutError(<urllib3.connection.HTTPSConnection object at 0x7fb5c83d6260>, 'Connection to api.wandb.ai timed out. (connect timeout=20)'))
2025-08-11 16:01:19,641 ERROR   MainThread:1341571 [wandb_init.py:init():841] encountered error: Run initialization has timed out after 90.0 sec. Please try increasing the timeout with the `init_timeout` setting: `wandb.init(settings=wandb.Settings(init_timeout=120))`.
2025-08-11 16:01:19,641 ERROR   MainThread:1341571 [wandb_init.py:init():1266] error in wandb.init()
Traceback (most recent call last):
  File "/opt/conda/envs/flow_grpo/lib/python3.10/site-packages/wandb/sdk/wandb_init.py", line 1256, in init
    return wi.init()
  File "/opt/conda/envs/flow_grpo/lib/python3.10/site-packages/wandb/sdk/wandb_init.py", line 847, in init
    raise error
wandb.errors.errors.CommError: Run initialization has timed out after 90.0 sec. Please try increasing the timeout with the `init_timeout` setting: `wandb.init(settings=wandb.Settings(init_timeout=120))`.
2025-08-11 16:03:51,966 WARNING MsgRouterThr:1341571 [router.py:message_loop():75] message_loop has been closed
